INFO:werkzeug: * Running on http://0.0.0.0:5000/ (Press CTRL+C to quit)
INFO:werkzeug: * Running on http://0.0.0.0:8086/ (Press CTRL+C to quit)
INFO:werkzeug:127.0.0.1 - - [24/May/2020 10:33:43] "POST /route HTTP/1.1" 401 -
ERROR:app:Exception on /route [POST]
Traceback (most recent call last):
  File "/home/lap11735/anaconda3/lib/python3.7/site-packages/flask/app.py", line 2446, in wsgi_app
    response = self.full_dispatch_request()
  File "/home/lap11735/anaconda3/lib/python3.7/site-packages/flask/app.py", line 1951, in full_dispatch_request
    rv = self.handle_user_exception(e)
  File "/home/lap11735/anaconda3/lib/python3.7/site-packages/flask/app.py", line 1820, in handle_user_exception
    reraise(exc_type, exc_value, tb)
  File "/home/lap11735/anaconda3/lib/python3.7/site-packages/flask/_compat.py", line 39, in reraise
    raise value
  File "/home/lap11735/anaconda3/lib/python3.7/site-packages/flask/app.py", line 1949, in full_dispatch_request
    rv = self.dispatch_request()
  File "/home/lap11735/anaconda3/lib/python3.7/site-packages/flask/app.py", line 1935, in dispatch_request
    return self.view_functions[rule.endpoint](**req.view_args)
  File "app.py", line 58, in wrapper
    return f(token.get('sub'), *args, **kwargs)
AttributeError: 'DecodeError' object has no attribute 'get'
INFO:werkzeug:127.0.0.1 - - [24/May/2020 10:34:46] "POST /route HTTP/1.1" 500 -
ERROR:app:Exception on /route [POST]
Traceback (most recent call last):
  File "/home/lap11735/anaconda3/lib/python3.7/site-packages/flask/app.py", line 2446, in wsgi_app
    response = self.full_dispatch_request()
  File "/home/lap11735/anaconda3/lib/python3.7/site-packages/flask/app.py", line 1951, in full_dispatch_request
    rv = self.handle_user_exception(e)
  File "/home/lap11735/anaconda3/lib/python3.7/site-packages/flask/app.py", line 1820, in handle_user_exception
    reraise(exc_type, exc_value, tb)
  File "/home/lap11735/anaconda3/lib/python3.7/site-packages/flask/_compat.py", line 39, in reraise
    raise value
  File "/home/lap11735/anaconda3/lib/python3.7/site-packages/flask/app.py", line 1949, in full_dispatch_request
    rv = self.dispatch_request()
  File "/home/lap11735/anaconda3/lib/python3.7/site-packages/flask/app.py", line 1935, in dispatch_request
    return self.view_functions[rule.endpoint](**req.view_args)
  File "app.py", line 58, in wrapper
    return f(token.get('sub'), *args, **kwargs)
AttributeError: 'DecodeError' object has no attribute 'get'
INFO:werkzeug:127.0.0.1 - - [24/May/2020 10:34:53] "POST /route HTTP/1.1" 500 -
INFO:werkzeug: * Running on http://0.0.0.0:8086/ (Press CTRL+C to quit)
ERROR:app:Exception on /route [POST]
Traceback (most recent call last):
  File "/home/lap11735/anaconda3/lib/python3.7/site-packages/flask/app.py", line 2446, in wsgi_app
    response = self.full_dispatch_request()
  File "/home/lap11735/anaconda3/lib/python3.7/site-packages/flask/app.py", line 1951, in full_dispatch_request
    rv = self.handle_user_exception(e)
  File "/home/lap11735/anaconda3/lib/python3.7/site-packages/flask/app.py", line 1820, in handle_user_exception
    reraise(exc_type, exc_value, tb)
  File "/home/lap11735/anaconda3/lib/python3.7/site-packages/flask/_compat.py", line 39, in reraise
    raise value
  File "/home/lap11735/anaconda3/lib/python3.7/site-packages/flask/app.py", line 1949, in full_dispatch_request
    rv = self.dispatch_request()
  File "/home/lap11735/anaconda3/lib/python3.7/site-packages/flask/app.py", line 1935, in dispatch_request
    return self.view_functions[rule.endpoint](**req.view_args)
  File "app.py", line 58, in wrapper
    return f(token.get('sub'), *args, **kwargs)
AttributeError: 'DecodeError' object has no attribute 'get'
INFO:werkzeug:127.0.0.1 - - [24/May/2020 10:35:03] "POST /route HTTP/1.1" 500 -
INFO:werkzeug:127.0.0.1 - - [24/May/2020 10:35:25] "POST / HTTP/1.1" 405 -
ERROR:app:Exception on /route [POST]
Traceback (most recent call last):
  File "/home/lap11735/anaconda3/lib/python3.7/site-packages/flask/app.py", line 2446, in wsgi_app
    response = self.full_dispatch_request()
  File "/home/lap11735/anaconda3/lib/python3.7/site-packages/flask/app.py", line 1951, in full_dispatch_request
    rv = self.handle_user_exception(e)
  File "/home/lap11735/anaconda3/lib/python3.7/site-packages/flask/app.py", line 1820, in handle_user_exception
    reraise(exc_type, exc_value, tb)
  File "/home/lap11735/anaconda3/lib/python3.7/site-packages/flask/_compat.py", line 39, in reraise
    raise value
  File "/home/lap11735/anaconda3/lib/python3.7/site-packages/flask/app.py", line 1949, in full_dispatch_request
    rv = self.dispatch_request()
  File "/home/lap11735/anaconda3/lib/python3.7/site-packages/flask/app.py", line 1935, in dispatch_request
    return self.view_functions[rule.endpoint](**req.view_args)
  File "app.py", line 58, in wrapper
    return f(token.get('sub'), *args, **kwargs)
AttributeError: 'DecodeError' object has no attribute 'get'
INFO:werkzeug:127.0.0.1 - - [24/May/2020 10:35:29] "POST /route HTTP/1.1" 500 -
INFO:werkzeug:127.0.0.1 - - [24/May/2020 10:35:38] "GET / HTTP/1.1" 200 -
ERROR:app:Exception on /route [POST]
Traceback (most recent call last):
  File "/home/lap11735/anaconda3/lib/python3.7/site-packages/flask/app.py", line 2446, in wsgi_app
    response = self.full_dispatch_request()
  File "/home/lap11735/anaconda3/lib/python3.7/site-packages/flask/app.py", line 1951, in full_dispatch_request
    rv = self.handle_user_exception(e)
  File "/home/lap11735/anaconda3/lib/python3.7/site-packages/flask/app.py", line 1820, in handle_user_exception
    reraise(exc_type, exc_value, tb)
  File "/home/lap11735/anaconda3/lib/python3.7/site-packages/flask/_compat.py", line 39, in reraise
    raise value
  File "/home/lap11735/anaconda3/lib/python3.7/site-packages/flask/app.py", line 1949, in full_dispatch_request
    rv = self.dispatch_request()
  File "/home/lap11735/anaconda3/lib/python3.7/site-packages/flask/app.py", line 1935, in dispatch_request
    return self.view_functions[rule.endpoint](**req.view_args)
  File "app.py", line 58, in wrapper
    return make_error("Unauthorized", 401)
AttributeError: 'DecodeError' object has no attribute 'get'
INFO:werkzeug:127.0.0.1 - - [24/May/2020 10:37:43] "POST /route HTTP/1.1" 500 -
INFO:werkzeug: * Running on http://0.0.0.0:8086/ (Press CTRL+C to quit)
ERROR:app:Exception on /route [POST]
Traceback (most recent call last):
  File "/home/lap11735/anaconda3/lib/python3.7/site-packages/flask/app.py", line 2446, in wsgi_app
    response = self.full_dispatch_request()
  File "/home/lap11735/anaconda3/lib/python3.7/site-packages/flask/app.py", line 1951, in full_dispatch_request
    rv = self.handle_user_exception(e)
  File "/home/lap11735/anaconda3/lib/python3.7/site-packages/flask/app.py", line 1820, in handle_user_exception
    reraise(exc_type, exc_value, tb)
  File "/home/lap11735/anaconda3/lib/python3.7/site-packages/flask/_compat.py", line 39, in reraise
    raise value
  File "/home/lap11735/anaconda3/lib/python3.7/site-packages/flask/app.py", line 1949, in full_dispatch_request
    rv = self.dispatch_request()
  File "/home/lap11735/anaconda3/lib/python3.7/site-packages/flask/app.py", line 1935, in dispatch_request
    return self.view_functions[rule.endpoint](**req.view_args)
  File "app.py", line 61, in wrapper
    return f(token.get('sub'), *args, **kwargs)
AttributeError: 'DecodeError' object has no attribute 'get'
INFO:werkzeug:127.0.0.1 - - [24/May/2020 10:38:30] "POST /route HTTP/1.1" 500 -
INFO:werkzeug: * Running on http://0.0.0.0:8086/ (Press CTRL+C to quit)
ERROR:app:Exception on /route [POST]
Traceback (most recent call last):
  File "/home/lap11735/anaconda3/lib/python3.7/site-packages/flask/app.py", line 2446, in wsgi_app
    response = self.full_dispatch_request()
  File "/home/lap11735/anaconda3/lib/python3.7/site-packages/flask/app.py", line 1951, in full_dispatch_request
    rv = self.handle_user_exception(e)
  File "/home/lap11735/anaconda3/lib/python3.7/site-packages/flask/app.py", line 1820, in handle_user_exception
    reraise(exc_type, exc_value, tb)
  File "/home/lap11735/anaconda3/lib/python3.7/site-packages/flask/_compat.py", line 39, in reraise
    raise value
  File "/home/lap11735/anaconda3/lib/python3.7/site-packages/flask/app.py", line 1949, in full_dispatch_request
    rv = self.dispatch_request()
  File "/home/lap11735/anaconda3/lib/python3.7/site-packages/flask/app.py", line 1935, in dispatch_request
    return self.view_functions[rule.endpoint](**req.view_args)
  File "app.py", line 61, in wrapper
    return f(token.get('sub'), *args, **kwargs)
AttributeError: 'DecodeError' object has no attribute 'get'
INFO:werkzeug:127.0.0.1 - - [24/May/2020 10:38:44] "POST /route HTTP/1.1" 500 -
INFO:werkzeug: * Running on http://0.0.0.0:8086/ (Press CTRL+C to quit)
ERROR:app:Exception on /route [POST]
Traceback (most recent call last):
  File "/home/lap11735/anaconda3/lib/python3.7/site-packages/flask/app.py", line 2446, in wsgi_app
    response = self.full_dispatch_request()
  File "/home/lap11735/anaconda3/lib/python3.7/site-packages/flask/app.py", line 1951, in full_dispatch_request
    rv = self.handle_user_exception(e)
  File "/home/lap11735/anaconda3/lib/python3.7/site-packages/flask/app.py", line 1820, in handle_user_exception
    reraise(exc_type, exc_value, tb)
  File "/home/lap11735/anaconda3/lib/python3.7/site-packages/flask/_compat.py", line 39, in reraise
    raise value
  File "/home/lap11735/anaconda3/lib/python3.7/site-packages/flask/app.py", line 1949, in full_dispatch_request
    rv = self.dispatch_request()
  File "/home/lap11735/anaconda3/lib/python3.7/site-packages/flask/app.py", line 1935, in dispatch_request
    return self.view_functions[rule.endpoint](**req.view_args)
  File "app.py", line 62, in wrapper
    return f(token.get('sub'), *args, **kwargs)
AttributeError: 'DecodeError' object has no attribute 'get'
INFO:werkzeug:127.0.0.1 - - [24/May/2020 10:39:05] "POST /route HTTP/1.1" 500 -
INFO:werkzeug: * Running on http://0.0.0.0:8086/ (Press CTRL+C to quit)
ERROR:app:Exception on /route [POST]
Traceback (most recent call last):
  File "/home/lap11735/anaconda3/lib/python3.7/site-packages/flask/app.py", line 2446, in wsgi_app
    response = self.full_dispatch_request()
  File "/home/lap11735/anaconda3/lib/python3.7/site-packages/flask/app.py", line 1951, in full_dispatch_request
    rv = self.handle_user_exception(e)
  File "/home/lap11735/anaconda3/lib/python3.7/site-packages/flask/app.py", line 1820, in handle_user_exception
    reraise(exc_type, exc_value, tb)
  File "/home/lap11735/anaconda3/lib/python3.7/site-packages/flask/_compat.py", line 39, in reraise
    raise value
  File "/home/lap11735/anaconda3/lib/python3.7/site-packages/flask/app.py", line 1949, in full_dispatch_request
    rv = self.dispatch_request()
  File "/home/lap11735/anaconda3/lib/python3.7/site-packages/flask/app.py", line 1935, in dispatch_request
    return self.view_functions[rule.endpoint](**req.view_args)
  File "app.py", line 61, in wrapper
    return f(token.get('sub'), *args, **kwargs)
AttributeError: 'DecodeError' object has no attribute 'get'
INFO:werkzeug:127.0.0.1 - - [24/May/2020 10:39:24] "POST /route HTTP/1.1" 500 -
INFO:werkzeug: * Running on http://0.0.0.0:8086/ (Press CTRL+C to quit)
ERROR:app:Exception on /route [POST]
Traceback (most recent call last):
  File "/home/lap11735/anaconda3/lib/python3.7/site-packages/flask/app.py", line 2446, in wsgi_app
    response = self.full_dispatch_request()
  File "/home/lap11735/anaconda3/lib/python3.7/site-packages/flask/app.py", line 1951, in full_dispatch_request
    rv = self.handle_user_exception(e)
  File "/home/lap11735/anaconda3/lib/python3.7/site-packages/flask/app.py", line 1820, in handle_user_exception
    reraise(exc_type, exc_value, tb)
  File "/home/lap11735/anaconda3/lib/python3.7/site-packages/flask/_compat.py", line 39, in reraise
    raise value
  File "/home/lap11735/anaconda3/lib/python3.7/site-packages/flask/app.py", line 1949, in full_dispatch_request
    rv = self.dispatch_request()
  File "/home/lap11735/anaconda3/lib/python3.7/site-packages/flask/app.py", line 1935, in dispatch_request
    return self.view_functions[rule.endpoint](**req.view_args)
  File "app.py", line 61, in wrapper
    return f(token.get('sub'), *args, **kwargs)
AttributeError: 'DecodeError' object has no attribute 'get'
INFO:werkzeug:127.0.0.1 - - [24/May/2020 10:39:50] "POST /route HTTP/1.1" 500 -
INFO:werkzeug: * Running on http://0.0.0.0:8086/ (Press CTRL+C to quit)
INFO:werkzeug:127.0.0.1 - - [24/May/2020 10:40:55] "POST /route HTTP/1.1" 200 -
INFO:werkzeug:127.0.0.1 - - [24/May/2020 10:42:46] "POST /route HTTP/1.1" 403 -
INFO:werkzeug: * Running on http://0.0.0.0:8086/ (Press CTRL+C to quit)
INFO:werkzeug:127.0.0.1 - - [24/May/2020 10:42:53] "POST /route HTTP/1.1" 200 -
INFO:werkzeug: * Running on http://0.0.0.0:8086/ (Press CTRL+C to quit)
INFO:werkzeug: * Running on http://0.0.0.0:8086/ (Press CTRL+C to quit)
INFO:werkzeug:127.0.0.1 - - [24/May/2020 10:43:28] "POST /route HTTP/1.1" 200 -
INFO:werkzeug: * Running on http://0.0.0.0:8086/ (Press CTRL+C to quit)
INFO:werkzeug:127.0.0.1 - - [24/May/2020 10:44:17] "POST /route HTTP/1.1" 200 -
INFO:werkzeug: * Running on http://0.0.0.0:8086/ (Press CTRL+C to quit)
ERROR:app:Exception on /recommender-places [POST]
Traceback (most recent call last):
  File "/home/lap11735/anaconda3/lib/python3.7/site-packages/flask/app.py", line 2446, in wsgi_app
    response = self.full_dispatch_request()
  File "/home/lap11735/anaconda3/lib/python3.7/site-packages/flask/app.py", line 1952, in full_dispatch_request
    return self.finalize_request(rv)
  File "/home/lap11735/anaconda3/lib/python3.7/site-packages/flask/app.py", line 1967, in finalize_request
    response = self.make_response(rv)
  File "/home/lap11735/anaconda3/lib/python3.7/site-packages/flask/app.py", line 2130, in make_response
    " {rv.__class__.__name__}.".format(rv=rv)
TypeError: The view function did not return a valid response. The return type must be a string, dict, tuple, Response instance, or WSGI callable, but it was a ndarray.
INFO:werkzeug:127.0.0.1 - - [24/May/2020 10:51:14] "POST /recommender-places HTTP/1.1" 500 -
INFO:werkzeug: * Running on http://0.0.0.0:8086/ (Press CTRL+C to quit)
INFO:werkzeug: * Running on http://0.0.0.0:8086/ (Press CTRL+C to quit)
ERROR:app:Exception on /recommender-places [POST]
Traceback (most recent call last):
  File "/home/lap11735/anaconda3/lib/python3.7/site-packages/flask/app.py", line 2446, in wsgi_app
    response = self.full_dispatch_request()
  File "/home/lap11735/anaconda3/lib/python3.7/site-packages/flask/app.py", line 1952, in full_dispatch_request
    return self.finalize_request(rv)
  File "/home/lap11735/anaconda3/lib/python3.7/site-packages/flask/app.py", line 1967, in finalize_request
    response = self.make_response(rv)
  File "/home/lap11735/anaconda3/lib/python3.7/site-packages/flask/app.py", line 2130, in make_response
    " {rv.__class__.__name__}.".format(rv=rv)
TypeError: The view function did not return a valid response. The return type must be a string, dict, tuple, Response instance, or WSGI callable, but it was a ndarray.
INFO:werkzeug:127.0.0.1 - - [24/May/2020 10:52:40] "POST /recommender-places HTTP/1.1" 500 -
ERROR:app:Exception on /recommender-places [POST]
Traceback (most recent call last):
  File "/home/lap11735/anaconda3/lib/python3.7/site-packages/flask/app.py", line 2446, in wsgi_app
    response = self.full_dispatch_request()
  File "/home/lap11735/anaconda3/lib/python3.7/site-packages/flask/app.py", line 1952, in full_dispatch_request
    return self.finalize_request(rv)
  File "/home/lap11735/anaconda3/lib/python3.7/site-packages/flask/app.py", line 1967, in finalize_request
    response = self.make_response(rv)
  File "/home/lap11735/anaconda3/lib/python3.7/site-packages/flask/app.py", line 2130, in make_response
    " {rv.__class__.__name__}.".format(rv=rv)
TypeError: The view function did not return a valid response. The return type must be a string, dict, tuple, Response instance, or WSGI callable, but it was a ndarray.
INFO:werkzeug:127.0.0.1 - - [24/May/2020 10:52:45] "POST /recommender-places HTTP/1.1" 500 -
INFO:werkzeug: * Running on http://0.0.0.0:8086/ (Press CTRL+C to quit)
ERROR:app:Exception on /recommender-places [POST]
Traceback (most recent call last):
  File "/home/lap11735/anaconda3/lib/python3.7/site-packages/flask/app.py", line 2446, in wsgi_app
    response = self.full_dispatch_request()
  File "/home/lap11735/anaconda3/lib/python3.7/site-packages/flask/app.py", line 1952, in full_dispatch_request
    return self.finalize_request(rv)
  File "/home/lap11735/anaconda3/lib/python3.7/site-packages/flask/app.py", line 1967, in finalize_request
    response = self.make_response(rv)
  File "/home/lap11735/anaconda3/lib/python3.7/site-packages/flask/app.py", line 2130, in make_response
    " {rv.__class__.__name__}.".format(rv=rv)
TypeError: The view function did not return a valid response. The return type must be a string, dict, tuple, Response instance, or WSGI callable, but it was a ndarray.
INFO:werkzeug:127.0.0.1 - - [24/May/2020 10:54:49] "POST /recommender-places HTTP/1.1" 500 -
INFO:werkzeug: * Running on http://0.0.0.0:8086/ (Press CTRL+C to quit)
ERROR:app:Exception on /recommender-places [POST]
Traceback (most recent call last):
  File "/home/lap11735/anaconda3/lib/python3.7/site-packages/flask/app.py", line 2446, in wsgi_app
    response = self.full_dispatch_request()
  File "/home/lap11735/anaconda3/lib/python3.7/site-packages/flask/app.py", line 1952, in full_dispatch_request
    return self.finalize_request(rv)
  File "/home/lap11735/anaconda3/lib/python3.7/site-packages/flask/app.py", line 1967, in finalize_request
    response = self.make_response(rv)
  File "/home/lap11735/anaconda3/lib/python3.7/site-packages/flask/app.py", line 2130, in make_response
    " {rv.__class__.__name__}.".format(rv=rv)
TypeError: The view function did not return a valid response. The return type must be a string, dict, tuple, Response instance, or WSGI callable, but it was a ndarray.
INFO:werkzeug:127.0.0.1 - - [24/May/2020 10:56:52] "POST /recommender-places HTTP/1.1" 500 -
INFO:werkzeug: * Running on http://0.0.0.0:8086/ (Press CTRL+C to quit)
ERROR:app:Exception on /recommender-places [POST]
Traceback (most recent call last):
  File "/home/lap11735/anaconda3/lib/python3.7/site-packages/flask/app.py", line 2446, in wsgi_app
    response = self.full_dispatch_request()
  File "/home/lap11735/anaconda3/lib/python3.7/site-packages/flask/app.py", line 1952, in full_dispatch_request
    return self.finalize_request(rv)
  File "/home/lap11735/anaconda3/lib/python3.7/site-packages/flask/app.py", line 1967, in finalize_request
    response = self.make_response(rv)
  File "/home/lap11735/anaconda3/lib/python3.7/site-packages/flask/app.py", line 2130, in make_response
    " {rv.__class__.__name__}.".format(rv=rv)
TypeError: The view function did not return a valid response. The return type must be a string, dict, tuple, Response instance, or WSGI callable, but it was a ndarray.
INFO:werkzeug:127.0.0.1 - - [24/May/2020 10:57:04] "POST /recommender-places HTTP/1.1" 500 -
INFO:werkzeug: * Running on http://0.0.0.0:8086/ (Press CTRL+C to quit)
ERROR:app:Exception on /recommender-places [POST]
Traceback (most recent call last):
  File "/home/lap11735/anaconda3/lib/python3.7/site-packages/flask/app.py", line 2446, in wsgi_app
    response = self.full_dispatch_request()
  File "/home/lap11735/anaconda3/lib/python3.7/site-packages/flask/app.py", line 1952, in full_dispatch_request
    return self.finalize_request(rv)
  File "/home/lap11735/anaconda3/lib/python3.7/site-packages/flask/app.py", line 1967, in finalize_request
    response = self.make_response(rv)
  File "/home/lap11735/anaconda3/lib/python3.7/site-packages/flask/app.py", line 2130, in make_response
    " {rv.__class__.__name__}.".format(rv=rv)
TypeError: The view function did not return a valid response. The return type must be a string, dict, tuple, Response instance, or WSGI callable, but it was a ndarray.
INFO:werkzeug:127.0.0.1 - - [24/May/2020 10:57:28] "POST /recommender-places HTTP/1.1" 500 -
INFO:werkzeug: * Running on http://0.0.0.0:8086/ (Press CTRL+C to quit)
ERROR:app:Exception on /recommender-places [POST]
Traceback (most recent call last):
  File "/home/lap11735/anaconda3/lib/python3.7/site-packages/flask/app.py", line 2446, in wsgi_app
    response = self.full_dispatch_request()
  File "/home/lap11735/anaconda3/lib/python3.7/site-packages/flask/app.py", line 1952, in full_dispatch_request
    return self.finalize_request(rv)
  File "/home/lap11735/anaconda3/lib/python3.7/site-packages/flask/app.py", line 1967, in finalize_request
    response = self.make_response(rv)
  File "/home/lap11735/anaconda3/lib/python3.7/site-packages/flask/app.py", line 2111, in make_response
    rv = jsonify(rv)
  File "/home/lap11735/anaconda3/lib/python3.7/site-packages/flask/json/__init__.py", line 370, in jsonify
    dumps(data, indent=indent, separators=separators) + "\n",
  File "/home/lap11735/anaconda3/lib/python3.7/site-packages/flask/json/__init__.py", line 211, in dumps
    rv = _json.dumps(obj, **kwargs)
  File "/home/lap11735/anaconda3/lib/python3.7/site-packages/simplejson/__init__.py", line 399, in dumps
    **kw).encode(obj)
  File "/home/lap11735/anaconda3/lib/python3.7/site-packages/simplejson/encoder.py", line 296, in encode
    chunks = self.iterencode(o, _one_shot=True)
  File "/home/lap11735/anaconda3/lib/python3.7/site-packages/simplejson/encoder.py", line 378, in iterencode
    return _iterencode(o, 0)
  File "/home/lap11735/anaconda3/lib/python3.7/site-packages/flask/json/__init__.py", line 100, in default
    return _json.JSONEncoder.default(self, o)
  File "/home/lap11735/anaconda3/lib/python3.7/site-packages/simplejson/encoder.py", line 273, in default
    o.__class__.__name__)
TypeError: Object of type ndarray is not JSON serializable
INFO:werkzeug:127.0.0.1 - - [24/May/2020 10:58:10] "POST /recommender-places HTTP/1.1" 500 -
ERROR:app:Exception on /recommender-places [POST]
Traceback (most recent call last):
  File "/home/lap11735/anaconda3/lib/python3.7/site-packages/flask/app.py", line 2446, in wsgi_app
    response = self.full_dispatch_request()
  File "/home/lap11735/anaconda3/lib/python3.7/site-packages/flask/app.py", line 1952, in full_dispatch_request
    return self.finalize_request(rv)
  File "/home/lap11735/anaconda3/lib/python3.7/site-packages/flask/app.py", line 1967, in finalize_request
    response = self.make_response(rv)
  File "/home/lap11735/anaconda3/lib/python3.7/site-packages/flask/app.py", line 2111, in make_response
    rv = jsonify(rv)
  File "/home/lap11735/anaconda3/lib/python3.7/site-packages/flask/json/__init__.py", line 370, in jsonify
    dumps(data, indent=indent, separators=separators) + "\n",
  File "/home/lap11735/anaconda3/lib/python3.7/site-packages/flask/json/__init__.py", line 211, in dumps
    rv = _json.dumps(obj, **kwargs)
  File "/home/lap11735/anaconda3/lib/python3.7/site-packages/simplejson/__init__.py", line 399, in dumps
    **kw).encode(obj)
  File "/home/lap11735/anaconda3/lib/python3.7/site-packages/simplejson/encoder.py", line 296, in encode
    chunks = self.iterencode(o, _one_shot=True)
  File "/home/lap11735/anaconda3/lib/python3.7/site-packages/simplejson/encoder.py", line 378, in iterencode
    return _iterencode(o, 0)
  File "/home/lap11735/anaconda3/lib/python3.7/site-packages/flask/json/__init__.py", line 100, in default
    return _json.JSONEncoder.default(self, o)
  File "/home/lap11735/anaconda3/lib/python3.7/site-packages/simplejson/encoder.py", line 273, in default
    o.__class__.__name__)
TypeError: Object of type ndarray is not JSON serializable
INFO:werkzeug:127.0.0.1 - - [24/May/2020 10:58:14] "POST /recommender-places HTTP/1.1" 500 -
INFO:werkzeug: * Running on http://0.0.0.0:8086/ (Press CTRL+C to quit)
ERROR:app:Exception on /recommender-places [POST]
Traceback (most recent call last):
  File "/home/lap11735/anaconda3/lib/python3.7/site-packages/flask/app.py", line 2446, in wsgi_app
    response = self.full_dispatch_request()
  File "/home/lap11735/anaconda3/lib/python3.7/site-packages/flask/app.py", line 1951, in full_dispatch_request
    rv = self.handle_user_exception(e)
  File "/home/lap11735/anaconda3/lib/python3.7/site-packages/flask/app.py", line 1820, in handle_user_exception
    reraise(exc_type, exc_value, tb)
  File "/home/lap11735/anaconda3/lib/python3.7/site-packages/flask/_compat.py", line 39, in reraise
    raise value
  File "/home/lap11735/anaconda3/lib/python3.7/site-packages/flask/app.py", line 1949, in full_dispatch_request
    rv = self.dispatch_request()
  File "/home/lap11735/anaconda3/lib/python3.7/site-packages/flask/app.py", line 1935, in dispatch_request
    return self.view_functions[rule.endpoint](**req.view_args)
  File "app.py", line 47, in wrapper
    return f(*args, **kwargs)
  File "app.py", line 109, in get_recommender_places
    return jsonify({"recommenderPlaces": result})
  File "/home/lap11735/anaconda3/lib/python3.7/site-packages/flask/json/__init__.py", line 370, in jsonify
    dumps(data, indent=indent, separators=separators) + "\n",
  File "/home/lap11735/anaconda3/lib/python3.7/site-packages/flask/json/__init__.py", line 211, in dumps
    rv = _json.dumps(obj, **kwargs)
  File "/home/lap11735/anaconda3/lib/python3.7/site-packages/simplejson/__init__.py", line 399, in dumps
    **kw).encode(obj)
  File "/home/lap11735/anaconda3/lib/python3.7/site-packages/simplejson/encoder.py", line 296, in encode
    chunks = self.iterencode(o, _one_shot=True)
  File "/home/lap11735/anaconda3/lib/python3.7/site-packages/simplejson/encoder.py", line 378, in iterencode
    return _iterencode(o, 0)
  File "/home/lap11735/anaconda3/lib/python3.7/site-packages/flask/json/__init__.py", line 100, in default
    return _json.JSONEncoder.default(self, o)
  File "/home/lap11735/anaconda3/lib/python3.7/site-packages/simplejson/encoder.py", line 273, in default
    o.__class__.__name__)
TypeError: Object of type ndarray is not JSON serializable
INFO:werkzeug:127.0.0.1 - - [24/May/2020 10:59:10] "POST /recommender-places HTTP/1.1" 500 -
ERROR:app:Exception on /recommender-places [POST]
Traceback (most recent call last):
  File "/home/lap11735/anaconda3/lib/python3.7/site-packages/flask/app.py", line 2446, in wsgi_app
    response = self.full_dispatch_request()
  File "/home/lap11735/anaconda3/lib/python3.7/site-packages/flask/app.py", line 1951, in full_dispatch_request
    rv = self.handle_user_exception(e)
  File "/home/lap11735/anaconda3/lib/python3.7/site-packages/flask/app.py", line 1820, in handle_user_exception
    reraise(exc_type, exc_value, tb)
  File "/home/lap11735/anaconda3/lib/python3.7/site-packages/flask/_compat.py", line 39, in reraise
    raise value
  File "/home/lap11735/anaconda3/lib/python3.7/site-packages/flask/app.py", line 1949, in full_dispatch_request
    rv = self.dispatch_request()
  File "/home/lap11735/anaconda3/lib/python3.7/site-packages/flask/app.py", line 1935, in dispatch_request
    return self.view_functions[rule.endpoint](**req.view_args)
  File "app.py", line 47, in wrapper
    return f(*args, **kwargs)
  File "app.py", line 109, in get_recommender_places
    return jsonify({"recommenderPlaces": result})
  File "/home/lap11735/anaconda3/lib/python3.7/site-packages/flask/json/__init__.py", line 370, in jsonify
    dumps(data, indent=indent, separators=separators) + "\n",
  File "/home/lap11735/anaconda3/lib/python3.7/site-packages/flask/json/__init__.py", line 211, in dumps
    rv = _json.dumps(obj, **kwargs)
  File "/home/lap11735/anaconda3/lib/python3.7/site-packages/simplejson/__init__.py", line 399, in dumps
    **kw).encode(obj)
  File "/home/lap11735/anaconda3/lib/python3.7/site-packages/simplejson/encoder.py", line 296, in encode
    chunks = self.iterencode(o, _one_shot=True)
  File "/home/lap11735/anaconda3/lib/python3.7/site-packages/simplejson/encoder.py", line 378, in iterencode
    return _iterencode(o, 0)
  File "/home/lap11735/anaconda3/lib/python3.7/site-packages/flask/json/__init__.py", line 100, in default
    return _json.JSONEncoder.default(self, o)
  File "/home/lap11735/anaconda3/lib/python3.7/site-packages/simplejson/encoder.py", line 273, in default
    o.__class__.__name__)
TypeError: Object of type ndarray is not JSON serializable
INFO:werkzeug:127.0.0.1 - - [24/May/2020 10:59:18] "POST /recommender-places HTTP/1.1" 500 -
ERROR:app:Exception on /recommender-places [POST]
Traceback (most recent call last):
  File "/home/lap11735/anaconda3/lib/python3.7/site-packages/flask/app.py", line 2446, in wsgi_app
    response = self.full_dispatch_request()
  File "/home/lap11735/anaconda3/lib/python3.7/site-packages/flask/app.py", line 1951, in full_dispatch_request
    rv = self.handle_user_exception(e)
  File "/home/lap11735/anaconda3/lib/python3.7/site-packages/flask/app.py", line 1820, in handle_user_exception
    reraise(exc_type, exc_value, tb)
  File "/home/lap11735/anaconda3/lib/python3.7/site-packages/flask/_compat.py", line 39, in reraise
    raise value
  File "/home/lap11735/anaconda3/lib/python3.7/site-packages/flask/app.py", line 1949, in full_dispatch_request
    rv = self.dispatch_request()
  File "/home/lap11735/anaconda3/lib/python3.7/site-packages/flask/app.py", line 1935, in dispatch_request
    return self.view_functions[rule.endpoint](**req.view_args)
  File "app.py", line 47, in wrapper
    return f(*args, **kwargs)
  File "app.py", line 109, in get_recommender_places
    return jsonify({"recommenderPlaces": result})
  File "/home/lap11735/anaconda3/lib/python3.7/site-packages/flask/json/__init__.py", line 370, in jsonify
    dumps(data, indent=indent, separators=separators) + "\n",
  File "/home/lap11735/anaconda3/lib/python3.7/site-packages/flask/json/__init__.py", line 211, in dumps
    rv = _json.dumps(obj, **kwargs)
  File "/home/lap11735/anaconda3/lib/python3.7/site-packages/simplejson/__init__.py", line 399, in dumps
    **kw).encode(obj)
  File "/home/lap11735/anaconda3/lib/python3.7/site-packages/simplejson/encoder.py", line 296, in encode
    chunks = self.iterencode(o, _one_shot=True)
  File "/home/lap11735/anaconda3/lib/python3.7/site-packages/simplejson/encoder.py", line 378, in iterencode
    return _iterencode(o, 0)
  File "/home/lap11735/anaconda3/lib/python3.7/site-packages/flask/json/__init__.py", line 100, in default
    return _json.JSONEncoder.default(self, o)
  File "/home/lap11735/anaconda3/lib/python3.7/site-packages/simplejson/encoder.py", line 273, in default
    o.__class__.__name__)
TypeError: Object of type ndarray is not JSON serializable
INFO:werkzeug:127.0.0.1 - - [24/May/2020 10:59:22] "POST /recommender-places HTTP/1.1" 500 -
INFO:werkzeug: * Running on http://0.0.0.0:8086/ (Press CTRL+C to quit)
ERROR:app:Exception on /recommender-places [POST]
Traceback (most recent call last):
  File "/home/lap11735/anaconda3/lib/python3.7/site-packages/flask/app.py", line 2446, in wsgi_app
    response = self.full_dispatch_request()
  File "/home/lap11735/anaconda3/lib/python3.7/site-packages/flask/app.py", line 1952, in full_dispatch_request
    return self.finalize_request(rv)
  File "/home/lap11735/anaconda3/lib/python3.7/site-packages/flask/app.py", line 1967, in finalize_request
    response = self.make_response(rv)
  File "/home/lap11735/anaconda3/lib/python3.7/site-packages/flask/app.py", line 2111, in make_response
    rv = jsonify(rv)
  File "/home/lap11735/anaconda3/lib/python3.7/site-packages/flask/json/__init__.py", line 370, in jsonify
    dumps(data, indent=indent, separators=separators) + "\n",
  File "/home/lap11735/anaconda3/lib/python3.7/site-packages/flask/json/__init__.py", line 211, in dumps
    rv = _json.dumps(obj, **kwargs)
  File "/home/lap11735/anaconda3/lib/python3.7/site-packages/simplejson/__init__.py", line 399, in dumps
    **kw).encode(obj)
  File "/home/lap11735/anaconda3/lib/python3.7/site-packages/simplejson/encoder.py", line 296, in encode
    chunks = self.iterencode(o, _one_shot=True)
  File "/home/lap11735/anaconda3/lib/python3.7/site-packages/simplejson/encoder.py", line 378, in iterencode
    return _iterencode(o, 0)
  File "/home/lap11735/anaconda3/lib/python3.7/site-packages/flask/json/__init__.py", line 100, in default
    return _json.JSONEncoder.default(self, o)
  File "/home/lap11735/anaconda3/lib/python3.7/site-packages/simplejson/encoder.py", line 273, in default
    o.__class__.__name__)
TypeError: Object of type ndarray is not JSON serializable
INFO:werkzeug:127.0.0.1 - - [24/May/2020 10:59:58] "POST /recommender-places HTTP/1.1" 500 -
INFO:werkzeug: * Running on http://0.0.0.0:8086/ (Press CTRL+C to quit)
INFO:werkzeug:127.0.0.1 - - [24/May/2020 11:01:12] "POST /recommender-places HTTP/1.1" 200 -
INFO:werkzeug: * Running on http://0.0.0.0:8086/ (Press CTRL+C to quit)
ERROR:app:Exception on /recommender-places [POST]
Traceback (most recent call last):
  File "/home/lap11735/anaconda3/lib/python3.7/site-packages/flask/app.py", line 2446, in wsgi_app
    response = self.full_dispatch_request()
  File "/home/lap11735/anaconda3/lib/python3.7/site-packages/flask/app.py", line 1952, in full_dispatch_request
    return self.finalize_request(rv)
  File "/home/lap11735/anaconda3/lib/python3.7/site-packages/flask/app.py", line 1967, in finalize_request
    response = self.make_response(rv)
  File "/home/lap11735/anaconda3/lib/python3.7/site-packages/flask/app.py", line 2130, in make_response
    " {rv.__class__.__name__}.".format(rv=rv)
TypeError: The view function did not return a valid response. The return type must be a string, dict, tuple, Response instance, or WSGI callable, but it was a list.
INFO:werkzeug:127.0.0.1 - - [24/May/2020 11:01:45] "POST /recommender-places HTTP/1.1" 500 -
ERROR:app:Exception on /recommender-places [POST]
Traceback (most recent call last):
  File "/home/lap11735/anaconda3/lib/python3.7/site-packages/flask/app.py", line 2446, in wsgi_app
    response = self.full_dispatch_request()
  File "/home/lap11735/anaconda3/lib/python3.7/site-packages/flask/app.py", line 1952, in full_dispatch_request
    return self.finalize_request(rv)
  File "/home/lap11735/anaconda3/lib/python3.7/site-packages/flask/app.py", line 1967, in finalize_request
    response = self.make_response(rv)
  File "/home/lap11735/anaconda3/lib/python3.7/site-packages/flask/app.py", line 2130, in make_response
    " {rv.__class__.__name__}.".format(rv=rv)
TypeError: The view function did not return a valid response. The return type must be a string, dict, tuple, Response instance, or WSGI callable, but it was a list.
INFO:werkzeug:127.0.0.1 - - [24/May/2020 11:01:54] "POST /recommender-places HTTP/1.1" 500 -
INFO:werkzeug: * Running on http://0.0.0.0:8086/ (Press CTRL+C to quit)
ERROR:app:Exception on /recommender-places [POST]
Traceback (most recent call last):
  File "/home/lap11735/anaconda3/lib/python3.7/site-packages/flask/app.py", line 2446, in wsgi_app
    response = self.full_dispatch_request()
  File "/home/lap11735/anaconda3/lib/python3.7/site-packages/flask/app.py", line 1951, in full_dispatch_request
    rv = self.handle_user_exception(e)
  File "/home/lap11735/anaconda3/lib/python3.7/site-packages/flask/app.py", line 1820, in handle_user_exception
    reraise(exc_type, exc_value, tb)
  File "/home/lap11735/anaconda3/lib/python3.7/site-packages/flask/_compat.py", line 39, in reraise
    raise value
  File "/home/lap11735/anaconda3/lib/python3.7/site-packages/flask/app.py", line 1949, in full_dispatch_request
    rv = self.dispatch_request()
  File "/home/lap11735/anaconda3/lib/python3.7/site-packages/flask/app.py", line 1935, in dispatch_request
    return self.view_functions[rule.endpoint](**req.view_args)
  File "app.py", line 47, in wrapper
    return f(*args, **kwargs)
  File "app.py", line 109, in get_recommender_places
    print(esult.tolist())
NameError: name 'esult' is not defined
INFO:werkzeug:127.0.0.1 - - [24/May/2020 11:02:18] "POST /recommender-places HTTP/1.1" 500 -
INFO:werkzeug: * Running on http://0.0.0.0:8086/ (Press CTRL+C to quit)
ERROR:app:Exception on /recommender-places [POST]
Traceback (most recent call last):
  File "/home/lap11735/anaconda3/lib/python3.7/site-packages/flask/app.py", line 2446, in wsgi_app
    response = self.full_dispatch_request()
  File "/home/lap11735/anaconda3/lib/python3.7/site-packages/flask/app.py", line 1952, in full_dispatch_request
    return self.finalize_request(rv)
  File "/home/lap11735/anaconda3/lib/python3.7/site-packages/flask/app.py", line 1967, in finalize_request
    response = self.make_response(rv)
  File "/home/lap11735/anaconda3/lib/python3.7/site-packages/flask/app.py", line 2130, in make_response
    " {rv.__class__.__name__}.".format(rv=rv)
TypeError: The view function did not return a valid response. The return type must be a string, dict, tuple, Response instance, or WSGI callable, but it was a list.
INFO:werkzeug:127.0.0.1 - - [24/May/2020 11:02:28] "POST /recommender-places HTTP/1.1" 500 -
INFO:werkzeug: * Running on http://0.0.0.0:8086/ (Press CTRL+C to quit)
INFO:werkzeug:127.0.0.1 - - [24/May/2020 11:02:50] "POST /recommender-places HTTP/1.1" 200 -
INFO:werkzeug: * Running on http://0.0.0.0:8086/ (Press CTRL+C to quit)
INFO:werkzeug:127.0.0.1 - - [24/May/2020 11:03:27] "POST /recommender-places/criteria HTTP/1.1" 200 -
INFO:werkzeug: * Running on http://0.0.0.0:8086/ (Press CTRL+C to quit)
ERROR:app:Exception on /recommender-places/criteria [POST]
Traceback (most recent call last):
  File "/home/lap11735/anaconda3/lib/python3.7/site-packages/flask/app.py", line 2446, in wsgi_app
    response = self.full_dispatch_request()
  File "/home/lap11735/anaconda3/lib/python3.7/site-packages/flask/app.py", line 1951, in full_dispatch_request
    rv = self.handle_user_exception(e)
  File "/home/lap11735/anaconda3/lib/python3.7/site-packages/flask/app.py", line 1820, in handle_user_exception
    reraise(exc_type, exc_value, tb)
  File "/home/lap11735/anaconda3/lib/python3.7/site-packages/flask/_compat.py", line 39, in reraise
    raise value
  File "/home/lap11735/anaconda3/lib/python3.7/site-packages/flask/app.py", line 1949, in full_dispatch_request
    rv = self.dispatch_request()
  File "/home/lap11735/anaconda3/lib/python3.7/site-packages/flask/app.py", line 1935, in dispatch_request
    return self.view_functions[rule.endpoint](**req.view_args)
  File "app.py", line 47, in wrapper
    return f(*args, **kwargs)
  File "app.py", line 106, in get_criteria_recommender_places
    result = get_recommender_by_criteria(criteria)
  File "/home/lap11735/Huan/thesis/travel-map-recommendation-system/Recommender/Criteria_Based_RS.py", line 15, in get_recommender_by_criteria
    data = [row['placeId'], row['avgRating'], row['spaceRating'], row['locationRating'], row['qualityRating'], row['serviceRating'], row['priceeRating']]
KeyError: 'priceeRating'
INFO:werkzeug:127.0.0.1 - - [24/May/2020 11:12:30] "POST /recommender-places/criteria HTTP/1.1" 500 -
INFO:werkzeug: * Running on http://0.0.0.0:8086/ (Press CTRL+C to quit)
ERROR:app:Exception on /recommender-places/criteria [POST]
Traceback (most recent call last):
  File "/home/lap11735/anaconda3/lib/python3.7/site-packages/flask/app.py", line 2446, in wsgi_app
    response = self.full_dispatch_request()
  File "/home/lap11735/anaconda3/lib/python3.7/site-packages/flask/app.py", line 1951, in full_dispatch_request
    rv = self.handle_user_exception(e)
  File "/home/lap11735/anaconda3/lib/python3.7/site-packages/flask/app.py", line 1820, in handle_user_exception
    reraise(exc_type, exc_value, tb)
  File "/home/lap11735/anaconda3/lib/python3.7/site-packages/flask/_compat.py", line 39, in reraise
    raise value
  File "/home/lap11735/anaconda3/lib/python3.7/site-packages/flask/app.py", line 1949, in full_dispatch_request
    rv = self.dispatch_request()
  File "/home/lap11735/anaconda3/lib/python3.7/site-packages/flask/app.py", line 1935, in dispatch_request
    return self.view_functions[rule.endpoint](**req.view_args)
  File "app.py", line 47, in wrapper
    return f(*args, **kwargs)
  File "app.py", line 106, in get_criteria_recommender_places
    result = get_recommender_by_criteria(criteria)
  File "/home/lap11735/Huan/thesis/travel-map-recommendation-system/Recommender/Criteria_Based_RS.py", line 15, in get_recommender_by_criteria
    data = [row['placeId'], row['avgRating'], row['spaceRating'], row['locationRating'], row['qualityRating'], row['serviceRating'], row['priceeRating']]
KeyError: 'priceeRating'
INFO:werkzeug:127.0.0.1 - - [24/May/2020 11:12:43] "POST /recommender-places/criteria HTTP/1.1" 500 -
ERROR:app:Exception on /recommender-places/criteria [POST]
Traceback (most recent call last):
  File "/home/lap11735/anaconda3/lib/python3.7/site-packages/flask/app.py", line 2446, in wsgi_app
    response = self.full_dispatch_request()
  File "/home/lap11735/anaconda3/lib/python3.7/site-packages/flask/app.py", line 1951, in full_dispatch_request
    rv = self.handle_user_exception(e)
  File "/home/lap11735/anaconda3/lib/python3.7/site-packages/flask/app.py", line 1820, in handle_user_exception
    reraise(exc_type, exc_value, tb)
  File "/home/lap11735/anaconda3/lib/python3.7/site-packages/flask/_compat.py", line 39, in reraise
    raise value
  File "/home/lap11735/anaconda3/lib/python3.7/site-packages/flask/app.py", line 1949, in full_dispatch_request
    rv = self.dispatch_request()
  File "/home/lap11735/anaconda3/lib/python3.7/site-packages/flask/app.py", line 1935, in dispatch_request
    return self.view_functions[rule.endpoint](**req.view_args)
  File "app.py", line 47, in wrapper
    return f(*args, **kwargs)
  File "app.py", line 106, in get_criteria_recommender_places
    result = get_recommender_by_criteria(criteria)
  File "/home/lap11735/Huan/thesis/travel-map-recommendation-system/Recommender/Criteria_Based_RS.py", line 15, in get_recommender_by_criteria
    data = [row['placeId'], row['avgRating'], row['spaceRating'], row['locationRating'], row['qualityRating'], row['serviceRating'], row['priceeRating']]
KeyError: 'priceeRating'
INFO:werkzeug:127.0.0.1 - - [24/May/2020 11:12:50] "POST /recommender-places/criteria HTTP/1.1" 500 -
INFO:werkzeug: * Running on http://0.0.0.0:8086/ (Press CTRL+C to quit)
ERROR:app:Exception on /recommender-places/criteria [POST]
Traceback (most recent call last):
  File "/home/lap11735/anaconda3/lib/python3.7/site-packages/flask/app.py", line 2446, in wsgi_app
    response = self.full_dispatch_request()
  File "/home/lap11735/anaconda3/lib/python3.7/site-packages/flask/app.py", line 1951, in full_dispatch_request
    rv = self.handle_user_exception(e)
  File "/home/lap11735/anaconda3/lib/python3.7/site-packages/flask/app.py", line 1820, in handle_user_exception
    reraise(exc_type, exc_value, tb)
  File "/home/lap11735/anaconda3/lib/python3.7/site-packages/flask/_compat.py", line 39, in reraise
    raise value
  File "/home/lap11735/anaconda3/lib/python3.7/site-packages/flask/app.py", line 1949, in full_dispatch_request
    rv = self.dispatch_request()
  File "/home/lap11735/anaconda3/lib/python3.7/site-packages/flask/app.py", line 1935, in dispatch_request
    return self.view_functions[rule.endpoint](**req.view_args)
  File "app.py", line 47, in wrapper
    return f(*args, **kwargs)
  File "app.py", line 106, in get_criteria_recommender_places
    result = get_recommender_by_criteria(criteria)
  File "/home/lap11735/Huan/thesis/travel-map-recommendation-system/Recommender/Criteria_Based_RS.py", line 16, in get_recommender_by_criteria
    data = [row['placeId'], row['avgRating'], row['spaceRating'], row['locationRating'], row['qualityRating'], row['serviceRating'], row['priceeRating']]
KeyError: 'priceeRating'
INFO:werkzeug:127.0.0.1 - - [24/May/2020 11:13:04] "POST /recommender-places/criteria HTTP/1.1" 500 -
INFO:werkzeug: * Running on http://0.0.0.0:8086/ (Press CTRL+C to quit)
ERROR:app:Exception on /recommender-places/criteria [POST]
Traceback (most recent call last):
  File "/home/lap11735/anaconda3/lib/python3.7/site-packages/flask/app.py", line 2446, in wsgi_app
    response = self.full_dispatch_request()
  File "/home/lap11735/anaconda3/lib/python3.7/site-packages/flask/app.py", line 1951, in full_dispatch_request
    rv = self.handle_user_exception(e)
  File "/home/lap11735/anaconda3/lib/python3.7/site-packages/flask/app.py", line 1820, in handle_user_exception
    reraise(exc_type, exc_value, tb)
  File "/home/lap11735/anaconda3/lib/python3.7/site-packages/flask/_compat.py", line 39, in reraise
    raise value
  File "/home/lap11735/anaconda3/lib/python3.7/site-packages/flask/app.py", line 1949, in full_dispatch_request
    rv = self.dispatch_request()
  File "/home/lap11735/anaconda3/lib/python3.7/site-packages/flask/app.py", line 1935, in dispatch_request
    return self.view_functions[rule.endpoint](**req.view_args)
  File "app.py", line 47, in wrapper
    return f(*args, **kwargs)
  File "app.py", line 106, in get_criteria_recommender_places
    result = get_recommender_by_criteria(criteria)
  File "/home/lap11735/Huan/thesis/travel-map-recommendation-system/Recommender/Criteria_Based_RS.py", line 15, in get_recommender_by_criteria
    data = [row['placeId'], row['avgRating'], row['spaceRating'], row['locationRating'], row['qualityRating'], row['serviceRating'], row['priceeRating']]
KeyError: 'priceeRating'
INFO:werkzeug:127.0.0.1 - - [24/May/2020 11:13:25] "POST /recommender-places/criteria HTTP/1.1" 500 -
INFO:werkzeug: * Running on http://0.0.0.0:8086/ (Press CTRL+C to quit)
ERROR:app:Exception on /recommender-places/criteria [POST]
Traceback (most recent call last):
  File "/home/lap11735/anaconda3/lib/python3.7/site-packages/flask/app.py", line 2446, in wsgi_app
    response = self.full_dispatch_request()
  File "/home/lap11735/anaconda3/lib/python3.7/site-packages/flask/app.py", line 1951, in full_dispatch_request
    rv = self.handle_user_exception(e)
  File "/home/lap11735/anaconda3/lib/python3.7/site-packages/flask/app.py", line 1820, in handle_user_exception
    reraise(exc_type, exc_value, tb)
  File "/home/lap11735/anaconda3/lib/python3.7/site-packages/flask/_compat.py", line 39, in reraise
    raise value
  File "/home/lap11735/anaconda3/lib/python3.7/site-packages/flask/app.py", line 1949, in full_dispatch_request
    rv = self.dispatch_request()
  File "/home/lap11735/anaconda3/lib/python3.7/site-packages/flask/app.py", line 1935, in dispatch_request
    return self.view_functions[rule.endpoint](**req.view_args)
  File "app.py", line 47, in wrapper
    return f(*args, **kwargs)
  File "app.py", line 106, in get_criteria_recommender_places
    result = get_recommender_by_criteria(criteria)
  File "/home/lap11735/Huan/thesis/travel-map-recommendation-system/Recommender/Criteria_Based_RS.py", line 16, in get_recommender_by_criteria
    data = [row['placeId'], row['avgRating'], row['spaceRating'], row['locationRating'], row['qualityRating'], row['serviceRating'], row['priceeRating']]
KeyError: 'priceeRating'
INFO:werkzeug:127.0.0.1 - - [24/May/2020 11:13:46] "POST /recommender-places/criteria HTTP/1.1" 500 -
INFO:werkzeug: * Running on http://0.0.0.0:8086/ (Press CTRL+C to quit)
ERROR:app:Exception on /recommender-places/criteria [POST]
Traceback (most recent call last):
  File "/home/lap11735/anaconda3/lib/python3.7/site-packages/flask/app.py", line 2446, in wsgi_app
    response = self.full_dispatch_request()
  File "/home/lap11735/anaconda3/lib/python3.7/site-packages/flask/app.py", line 1951, in full_dispatch_request
    rv = self.handle_user_exception(e)
  File "/home/lap11735/anaconda3/lib/python3.7/site-packages/flask/app.py", line 1820, in handle_user_exception
    reraise(exc_type, exc_value, tb)
  File "/home/lap11735/anaconda3/lib/python3.7/site-packages/flask/_compat.py", line 39, in reraise
    raise value
  File "/home/lap11735/anaconda3/lib/python3.7/site-packages/flask/app.py", line 1949, in full_dispatch_request
    rv = self.dispatch_request()
  File "/home/lap11735/anaconda3/lib/python3.7/site-packages/flask/app.py", line 1935, in dispatch_request
    return self.view_functions[rule.endpoint](**req.view_args)
  File "app.py", line 47, in wrapper
    return f(*args, **kwargs)
  File "app.py", line 106, in get_criteria_recommender_places
    result = get_recommender_by_criteria(criteria)
  File "/home/lap11735/Huan/thesis/travel-map-recommendation-system/Recommender/Criteria_Based_RS.py", line 19, in get_recommender_by_criteria
    go = dt[:,-5:]
TypeError: list indices must be integers or slices, not tuple
INFO:werkzeug:127.0.0.1 - - [24/May/2020 11:14:21] "POST /recommender-places/criteria HTTP/1.1" 500 -
INFO:werkzeug: * Running on http://0.0.0.0:8086/ (Press CTRL+C to quit)
ERROR:app:Exception on /recommender-places/criteria [POST]
Traceback (most recent call last):
  File "/home/lap11735/anaconda3/lib/python3.7/site-packages/flask/app.py", line 2446, in wsgi_app
    response = self.full_dispatch_request()
  File "/home/lap11735/anaconda3/lib/python3.7/site-packages/flask/app.py", line 1951, in full_dispatch_request
    rv = self.handle_user_exception(e)
  File "/home/lap11735/anaconda3/lib/python3.7/site-packages/flask/app.py", line 1820, in handle_user_exception
    reraise(exc_type, exc_value, tb)
  File "/home/lap11735/anaconda3/lib/python3.7/site-packages/flask/_compat.py", line 39, in reraise
    raise value
  File "/home/lap11735/anaconda3/lib/python3.7/site-packages/flask/app.py", line 1949, in full_dispatch_request
    rv = self.dispatch_request()
  File "/home/lap11735/anaconda3/lib/python3.7/site-packages/flask/app.py", line 1935, in dispatch_request
    return self.view_functions[rule.endpoint](**req.view_args)
  File "app.py", line 47, in wrapper
    return f(*args, **kwargs)
  File "app.py", line 106, in get_criteria_recommender_places
    result = get_recommender_by_criteria(criteria)
  File "/home/lap11735/Huan/thesis/travel-map-recommendation-system/Recommender/Criteria_Based_RS.py", line 20, in get_recommender_by_criteria
    go = dt[:,-5:]
TypeError: list indices must be integers or slices, not tuple
INFO:werkzeug:127.0.0.1 - - [24/May/2020 11:14:36] "POST /recommender-places/criteria HTTP/1.1" 500 -
INFO:werkzeug: * Running on http://0.0.0.0:8086/ (Press CTRL+C to quit)
ERROR:app:Exception on /recommender-places/criteria [POST]
Traceback (most recent call last):
  File "/home/lap11735/anaconda3/lib/python3.7/site-packages/flask/app.py", line 2446, in wsgi_app
    response = self.full_dispatch_request()
  File "/home/lap11735/anaconda3/lib/python3.7/site-packages/flask/app.py", line 1951, in full_dispatch_request
    rv = self.handle_user_exception(e)
  File "/home/lap11735/anaconda3/lib/python3.7/site-packages/flask/app.py", line 1820, in handle_user_exception
    reraise(exc_type, exc_value, tb)
  File "/home/lap11735/anaconda3/lib/python3.7/site-packages/flask/_compat.py", line 39, in reraise
    raise value
  File "/home/lap11735/anaconda3/lib/python3.7/site-packages/flask/app.py", line 1949, in full_dispatch_request
    rv = self.dispatch_request()
  File "/home/lap11735/anaconda3/lib/python3.7/site-packages/flask/app.py", line 1935, in dispatch_request
    return self.view_functions[rule.endpoint](**req.view_args)
  File "app.py", line 47, in wrapper
    return f(*args, **kwargs)
  File "app.py", line 106, in get_criteria_recommender_places
    result = get_recommender_by_criteria(criteria)
  File "/home/lap11735/Huan/thesis/travel-map-recommendation-system/Recommender/Criteria_Based_RS.py", line 21, in get_recommender_by_criteria
    go = dt[:,-5:]
TypeError: list indices must be integers or slices, not tuple
INFO:werkzeug:127.0.0.1 - - [24/May/2020 11:15:03] "POST /recommender-places/criteria HTTP/1.1" 500 -
ERROR:app:Exception on /recommender-places/criteria [POST]
Traceback (most recent call last):
  File "/home/lap11735/anaconda3/lib/python3.7/site-packages/flask/app.py", line 2446, in wsgi_app
    response = self.full_dispatch_request()
  File "/home/lap11735/anaconda3/lib/python3.7/site-packages/flask/app.py", line 1951, in full_dispatch_request
    rv = self.handle_user_exception(e)
  File "/home/lap11735/anaconda3/lib/python3.7/site-packages/flask/app.py", line 1820, in handle_user_exception
    reraise(exc_type, exc_value, tb)
  File "/home/lap11735/anaconda3/lib/python3.7/site-packages/flask/_compat.py", line 39, in reraise
    raise value
  File "/home/lap11735/anaconda3/lib/python3.7/site-packages/flask/app.py", line 1949, in full_dispatch_request
    rv = self.dispatch_request()
  File "/home/lap11735/anaconda3/lib/python3.7/site-packages/flask/app.py", line 1935, in dispatch_request
    return self.view_functions[rule.endpoint](**req.view_args)
  File "app.py", line 47, in wrapper
    return f(*args, **kwargs)
  File "app.py", line 106, in get_criteria_recommender_places
    result = get_recommender_by_criteria(criteria)
  File "/home/lap11735/Huan/thesis/travel-map-recommendation-system/Recommender/Criteria_Based_RS.py", line 21, in get_recommender_by_criteria
    print('ok')
TypeError: list indices must be integers or slices, not tuple
INFO:werkzeug:127.0.0.1 - - [24/May/2020 11:16:06] "POST /recommender-places/criteria HTTP/1.1" 500 -
INFO:werkzeug: * Running on http://0.0.0.0:8086/ (Press CTRL+C to quit)
ERROR:app:Exception on /recommender-places/criteria [POST]
Traceback (most recent call last):
  File "/home/lap11735/anaconda3/lib/python3.7/site-packages/flask/app.py", line 2446, in wsgi_app
    response = self.full_dispatch_request()
  File "/home/lap11735/anaconda3/lib/python3.7/site-packages/flask/app.py", line 1951, in full_dispatch_request
    rv = self.handle_user_exception(e)
  File "/home/lap11735/anaconda3/lib/python3.7/site-packages/flask/app.py", line 1820, in handle_user_exception
    reraise(exc_type, exc_value, tb)
  File "/home/lap11735/anaconda3/lib/python3.7/site-packages/flask/_compat.py", line 39, in reraise
    raise value
  File "/home/lap11735/anaconda3/lib/python3.7/site-packages/flask/app.py", line 1949, in full_dispatch_request
    rv = self.dispatch_request()
  File "/home/lap11735/anaconda3/lib/python3.7/site-packages/flask/app.py", line 1935, in dispatch_request
    return self.view_functions[rule.endpoint](**req.view_args)
  File "app.py", line 47, in wrapper
    return f(*args, **kwargs)
  File "app.py", line 106, in get_criteria_recommender_places
    result = get_recommender_by_criteria(criteria)
  File "/home/lap11735/Huan/thesis/travel-map-recommendation-system/Recommender/Criteria_Based_RS.py", line 22, in get_recommender_by_criteria
    go = dt[:,-5:]
TypeError: list indices must be integers or slices, not tuple
INFO:werkzeug:127.0.0.1 - - [24/May/2020 11:16:10] "POST /recommender-places/criteria HTTP/1.1" 500 -
INFO:werkzeug: * Running on http://0.0.0.0:8086/ (Press CTRL+C to quit)
ERROR:app:Exception on /recommender-places/criteria [POST]
Traceback (most recent call last):
  File "/home/lap11735/anaconda3/lib/python3.7/site-packages/flask/app.py", line 2446, in wsgi_app
    response = self.full_dispatch_request()
  File "/home/lap11735/anaconda3/lib/python3.7/site-packages/flask/app.py", line 1951, in full_dispatch_request
    rv = self.handle_user_exception(e)
  File "/home/lap11735/anaconda3/lib/python3.7/site-packages/flask/app.py", line 1820, in handle_user_exception
    reraise(exc_type, exc_value, tb)
  File "/home/lap11735/anaconda3/lib/python3.7/site-packages/flask/_compat.py", line 39, in reraise
    raise value
  File "/home/lap11735/anaconda3/lib/python3.7/site-packages/flask/app.py", line 1949, in full_dispatch_request
    rv = self.dispatch_request()
  File "/home/lap11735/anaconda3/lib/python3.7/site-packages/flask/app.py", line 1935, in dispatch_request
    return self.view_functions[rule.endpoint](**req.view_args)
  File "app.py", line 47, in wrapper
    return f(*args, **kwargs)
  File "app.py", line 106, in get_criteria_recommender_places
    result = get_recommender_by_criteria(criteria)
  File "/home/lap11735/Huan/thesis/travel-map-recommendation-system/Recommender/Criteria_Based_RS.py", line 19, in get_recommender_by_criteria
    go = dt[:,-5:]
TypeError: list indices must be integers or slices, not tuple
INFO:werkzeug:127.0.0.1 - - [24/May/2020 11:16:44] "POST /recommender-places/criteria HTTP/1.1" 500 -
ERROR:app:Exception on /recommender-places/criteria [POST]
Traceback (most recent call last):
  File "/home/lap11735/anaconda3/lib/python3.7/site-packages/flask/app.py", line 2446, in wsgi_app
    response = self.full_dispatch_request()
  File "/home/lap11735/anaconda3/lib/python3.7/site-packages/flask/app.py", line 1951, in full_dispatch_request
    rv = self.handle_user_exception(e)
  File "/home/lap11735/anaconda3/lib/python3.7/site-packages/flask/app.py", line 1820, in handle_user_exception
    reraise(exc_type, exc_value, tb)
  File "/home/lap11735/anaconda3/lib/python3.7/site-packages/flask/_compat.py", line 39, in reraise
    raise value
  File "/home/lap11735/anaconda3/lib/python3.7/site-packages/flask/app.py", line 1949, in full_dispatch_request
    rv = self.dispatch_request()
  File "/home/lap11735/anaconda3/lib/python3.7/site-packages/flask/app.py", line 1935, in dispatch_request
    return self.view_functions[rule.endpoint](**req.view_args)
  File "app.py", line 47, in wrapper
    return f(*args, **kwargs)
  File "app.py", line 106, in get_criteria_recommender_places
    result = get_recommender_by_criteria(criteria)
  File "/home/lap11735/Huan/thesis/travel-map-recommendation-system/Recommender/Criteria_Based_RS.py", line 19, in get_recommender_by_criteria
    go = dt[:,-5:]
TypeError: list indices must be integers or slices, not tuple
INFO:werkzeug:127.0.0.1 - - [24/May/2020 11:16:46] "POST /recommender-places/criteria HTTP/1.1" 500 -
INFO:werkzeug: * Running on http://0.0.0.0:8086/ (Press CTRL+C to quit)
ERROR:app:Exception on /recommender-places/criteria [POST]
Traceback (most recent call last):
  File "/home/lap11735/anaconda3/lib/python3.7/site-packages/flask/app.py", line 2446, in wsgi_app
    response = self.full_dispatch_request()
  File "/home/lap11735/anaconda3/lib/python3.7/site-packages/flask/app.py", line 1951, in full_dispatch_request
    rv = self.handle_user_exception(e)
  File "/home/lap11735/anaconda3/lib/python3.7/site-packages/flask/app.py", line 1820, in handle_user_exception
    reraise(exc_type, exc_value, tb)
  File "/home/lap11735/anaconda3/lib/python3.7/site-packages/flask/_compat.py", line 39, in reraise
    raise value
  File "/home/lap11735/anaconda3/lib/python3.7/site-packages/flask/app.py", line 1949, in full_dispatch_request
    rv = self.dispatch_request()
  File "/home/lap11735/anaconda3/lib/python3.7/site-packages/flask/app.py", line 1935, in dispatch_request
    return self.view_functions[rule.endpoint](**req.view_args)
  File "app.py", line 47, in wrapper
    return f(*args, **kwargs)
  File "app.py", line 106, in get_criteria_recommender_places
    result = get_recommender_by_criteria(criteria)
  File "/home/lap11735/Huan/thesis/travel-map-recommendation-system/Recommender/Criteria_Based_RS.py", line 19, in get_recommender_by_criteria
    go = dt[:,-5:]
TypeError: list indices must be integers or slices, not tuple
INFO:werkzeug:127.0.0.1 - - [24/May/2020 11:16:56] "POST /recommender-places/criteria HTTP/1.1" 500 -
INFO:werkzeug: * Running on http://0.0.0.0:8086/ (Press CTRL+C to quit)
ERROR:app:Exception on /recommender-places/criteria [POST]
Traceback (most recent call last):
  File "/home/lap11735/anaconda3/lib/python3.7/site-packages/flask/app.py", line 2446, in wsgi_app
    response = self.full_dispatch_request()
  File "/home/lap11735/anaconda3/lib/python3.7/site-packages/flask/app.py", line 1951, in full_dispatch_request
    rv = self.handle_user_exception(e)
  File "/home/lap11735/anaconda3/lib/python3.7/site-packages/flask/app.py", line 1820, in handle_user_exception
    reraise(exc_type, exc_value, tb)
  File "/home/lap11735/anaconda3/lib/python3.7/site-packages/flask/_compat.py", line 39, in reraise
    raise value
  File "/home/lap11735/anaconda3/lib/python3.7/site-packages/flask/app.py", line 1949, in full_dispatch_request
    rv = self.dispatch_request()
  File "/home/lap11735/anaconda3/lib/python3.7/site-packages/flask/app.py", line 1935, in dispatch_request
    return self.view_functions[rule.endpoint](**req.view_args)
  File "app.py", line 47, in wrapper
    return f(*args, **kwargs)
  File "app.py", line 106, in get_criteria_recommender_places
    result = get_recommender_by_criteria(criteria)
  File "/home/lap11735/Huan/thesis/travel-map-recommendation-system/Recommender/Criteria_Based_RS.py", line 19, in get_recommender_by_criteria
    go = dt[:,-5:]
TypeError: list indices must be integers or slices, not tuple
INFO:werkzeug:127.0.0.1 - - [24/May/2020 11:17:08] "POST /recommender-places/criteria HTTP/1.1" 500 -
INFO:werkzeug: * Running on http://0.0.0.0:8086/ (Press CTRL+C to quit)
ERROR:app:Exception on /recommender-places/criteria [POST]
Traceback (most recent call last):
  File "/home/lap11735/anaconda3/lib/python3.7/site-packages/flask/app.py", line 2446, in wsgi_app
    response = self.full_dispatch_request()
  File "/home/lap11735/anaconda3/lib/python3.7/site-packages/flask/app.py", line 1951, in full_dispatch_request
    rv = self.handle_user_exception(e)
  File "/home/lap11735/anaconda3/lib/python3.7/site-packages/flask/app.py", line 1820, in handle_user_exception
    reraise(exc_type, exc_value, tb)
  File "/home/lap11735/anaconda3/lib/python3.7/site-packages/flask/_compat.py", line 39, in reraise
    raise value
  File "/home/lap11735/anaconda3/lib/python3.7/site-packages/flask/app.py", line 1949, in full_dispatch_request
    rv = self.dispatch_request()
  File "/home/lap11735/anaconda3/lib/python3.7/site-packages/flask/app.py", line 1935, in dispatch_request
    return self.view_functions[rule.endpoint](**req.view_args)
  File "app.py", line 47, in wrapper
    return f(*args, **kwargs)
  File "app.py", line 106, in get_criteria_recommender_places
    result = get_recommender_by_criteria(criteria)
  File "/home/lap11735/Huan/thesis/travel-map-recommendation-system/Recommender/Criteria_Based_RS.py", line 20, in get_recommender_by_criteria
    go = dt[:,-5:]
TypeError: list indices must be integers or slices, not tuple
INFO:werkzeug:127.0.0.1 - - [24/May/2020 11:17:18] "POST /recommender-places/criteria HTTP/1.1" 500 -
INFO:werkzeug: * Running on http://0.0.0.0:8086/ (Press CTRL+C to quit)
ERROR:app:Exception on /recommender-places/criteria [POST]
Traceback (most recent call last):
  File "/home/lap11735/anaconda3/lib/python3.7/site-packages/flask/app.py", line 2446, in wsgi_app
    response = self.full_dispatch_request()
  File "/home/lap11735/anaconda3/lib/python3.7/site-packages/flask/app.py", line 1951, in full_dispatch_request
    rv = self.handle_user_exception(e)
  File "/home/lap11735/anaconda3/lib/python3.7/site-packages/flask/app.py", line 1820, in handle_user_exception
    reraise(exc_type, exc_value, tb)
  File "/home/lap11735/anaconda3/lib/python3.7/site-packages/flask/_compat.py", line 39, in reraise
    raise value
  File "/home/lap11735/anaconda3/lib/python3.7/site-packages/flask/app.py", line 1949, in full_dispatch_request
    rv = self.dispatch_request()
  File "/home/lap11735/anaconda3/lib/python3.7/site-packages/flask/app.py", line 1935, in dispatch_request
    return self.view_functions[rule.endpoint](**req.view_args)
  File "app.py", line 47, in wrapper
    return f(*args, **kwargs)
  File "app.py", line 106, in get_criteria_recommender_places
    result = get_recommender_by_criteria(criteria)
  File "/home/lap11735/Huan/thesis/travel-map-recommendation-system/Recommender/Criteria_Based_RS.py", line 19, in get_recommender_by_criteria
    print(dt[:,-5:])
TypeError: list indices must be integers or slices, not tuple
INFO:werkzeug:127.0.0.1 - - [24/May/2020 11:17:32] "POST /recommender-places/criteria HTTP/1.1" 500 -
INFO:werkzeug: * Running on http://0.0.0.0:8086/ (Press CTRL+C to quit)
INFO:werkzeug:127.0.0.1 - - [24/May/2020 11:19:02] "POST /recommender-places/criteria HTTP/1.1" 200 -
INFO:werkzeug: * Running on http://0.0.0.0:8086/ (Press CTRL+C to quit)
INFO:werkzeug:127.0.0.1 - - [24/May/2020 11:21:04] "POST /recommender-places/criteria HTTP/1.1" 200 -
INFO:werkzeug:127.0.0.1 - - [24/May/2020 11:27:19] "POST /recommender-places/criteria HTTP/1.1" 200 -
INFO:werkzeug:127.0.0.1 - - [24/May/2020 11:28:28] "POST /recommender-places/criteria HTTP/1.1" 200 -
INFO:werkzeug:127.0.0.1 - - [24/May/2020 11:29:00] "POST /recommender-places/criteria HTTP/1.1" 200 -
INFO:werkzeug:127.0.0.1 - - [24/May/2020 11:29:44] "POST /recommender-places/criteria HTTP/1.1" 200 -
INFO:werkzeug:127.0.0.1 - - [24/May/2020 11:29:46] "POST /recommender-places/criteria HTTP/1.1" 200 -
INFO:werkzeug:127.0.0.1 - - [24/May/2020 11:29:52] "POST /recommender-places/criteria HTTP/1.1" 200 -
INFO:werkzeug:127.0.0.1 - - [24/May/2020 11:29:54] "POST /recommender-places/criteria HTTP/1.1" 200 -
INFO:werkzeug:127.0.0.1 - - [24/May/2020 11:35:48] "POST /recommender-places/criteria HTTP/1.1" 200 -
INFO:werkzeug:127.0.0.1 - - [24/May/2020 11:35:56] "POST /recommender-places/criteria HTTP/1.1" 200 -
INFO:werkzeug:127.0.0.1 - - [24/May/2020 11:37:17] "POST /recommender-places/criteria HTTP/1.1" 200 -
INFO:werkzeug:127.0.0.1 - - [24/May/2020 11:37:59] "POST /recommender-places/criteria HTTP/1.1" 200 -
INFO:werkzeug:127.0.0.1 - - [24/May/2020 11:38:09] "POST /recommender-places/criteria HTTP/1.1" 200 -
INFO:werkzeug:127.0.0.1 - - [24/May/2020 11:40:07] "POST /recommender-places/criteria HTTP/1.1" 200 -
INFO:werkzeug:127.0.0.1 - - [24/May/2020 11:40:36] "POST /recommender-places/criteria HTTP/1.1" 200 -
INFO:werkzeug:127.0.0.1 - - [24/May/2020 11:42:34] "POST /recommender-places/criteria HTTP/1.1" 200 -
INFO:werkzeug:127.0.0.1 - - [24/May/2020 11:42:51] "POST /recommender-places/criteria HTTP/1.1" 200 -
INFO:werkzeug:127.0.0.1 - - [24/May/2020 11:43:32] "POST /recommender-places/criteria HTTP/1.1" 200 -
INFO:werkzeug:127.0.0.1 - - [24/May/2020 11:43:33] "POST /recommender-places/criteria HTTP/1.1" 200 -
INFO:werkzeug:127.0.0.1 - - [24/May/2020 11:45:04] "POST /recommender-places/criteria HTTP/1.1" 200 -
INFO:werkzeug:127.0.0.1 - - [24/May/2020 11:47:48] "POST /recommender-places/criteria HTTP/1.1" 200 -
INFO:werkzeug:127.0.0.1 - - [24/May/2020 11:48:27] "POST /recommender-places/criteria HTTP/1.1" 200 -
INFO:werkzeug:127.0.0.1 - - [24/May/2020 11:48:42] "POST /recommender-places/criteria HTTP/1.1" 200 -
INFO:werkzeug:127.0.0.1 - - [24/May/2020 11:48:50] "POST /recommender-places/criteria HTTP/1.1" 200 -
INFO:werkzeug:127.0.0.1 - - [24/May/2020 11:50:07] "POST /recommender-places/criteria HTTP/1.1" 200 -
INFO:werkzeug: * Running on http://0.0.0.0:8086/ (Press CTRL+C to quit)
INFO:werkzeug:127.0.0.1 - - [24/May/2020 15:04:09] "POST /recommender-places/criteria HTTP/1.1" 200 -
INFO:werkzeug:127.0.0.1 - - [24/May/2020 15:04:28] "POST /recommender-places/criteria HTTP/1.1" 200 -
INFO:werkzeug:127.0.0.1 - - [24/May/2020 15:06:44] "POST /recommender-places/criteria HTTP/1.1" 200 -
INFO:werkzeug:127.0.0.1 - - [24/May/2020 15:07:52] "POST /recommender-places/criteria HTTP/1.1" 200 -
INFO:werkzeug:127.0.0.1 - - [24/May/2020 15:08:55] "POST /recommender-places/criteria HTTP/1.1" 200 -
INFO:werkzeug:127.0.0.1 - - [24/May/2020 15:10:41] "POST /recommender-places/criteria HTTP/1.1" 200 -
INFO:werkzeug:127.0.0.1 - - [24/May/2020 15:51:27] "POST /recommender-places/criteria HTTP/1.1" 200 -
INFO:werkzeug:127.0.0.1 - - [24/May/2020 15:54:30] "POST /recommender-places/criteria HTTP/1.1" 200 -
INFO:werkzeug:127.0.0.1 - - [24/May/2020 15:56:34] "POST /recommender-places/criteria HTTP/1.1" 200 -
INFO:werkzeug:127.0.0.1 - - [24/May/2020 16:03:59] "POST /recommender-places/criteria HTTP/1.1" 200 -
INFO:werkzeug:127.0.0.1 - - [24/May/2020 16:05:21] "POST /recommender-places/criteria HTTP/1.1" 200 -
INFO:werkzeug:127.0.0.1 - - [24/May/2020 16:06:41] "POST /recommender-places/criteria HTTP/1.1" 200 -
INFO:werkzeug:127.0.0.1 - - [24/May/2020 16:15:49] "POST /recommender-places/criteria HTTP/1.1" 200 -
INFO:werkzeug:127.0.0.1 - - [24/May/2020 21:36:27] "POST /recommender-places/criteria HTTP/1.1" 200 -
INFO:werkzeug:127.0.0.1 - - [24/May/2020 21:36:51] "POST /recommender-places/criteria HTTP/1.1" 200 -
INFO:werkzeug:127.0.0.1 - - [24/May/2020 22:08:18] "POST /recommender-places/criteria HTTP/1.1" 200 -
INFO:werkzeug:127.0.0.1 - - [24/May/2020 22:35:59] "POST /recommender-places/criteria HTTP/1.1" 200 -
INFO:werkzeug:127.0.0.1 - - [24/May/2020 22:36:18] "POST /recommender-places/criteria HTTP/1.1" 200 -
INFO:werkzeug:127.0.0.1 - - [24/May/2020 22:54:34] "POST /recommender-places/criteria HTTP/1.1" 200 -
INFO:werkzeug:127.0.0.1 - - [24/May/2020 22:58:38] "POST /recommender-places/criteria HTTP/1.1" 200 -
INFO:werkzeug:127.0.0.1 - - [24/May/2020 23:04:36] "POST /recommender-places/criteria HTTP/1.1" 200 -
INFO:werkzeug:127.0.0.1 - - [24/May/2020 23:07:41] "POST /recommender-places/criteria HTTP/1.1" 200 -
INFO:werkzeug:127.0.0.1 - - [24/May/2020 23:08:14] "POST /recommender-places/criteria HTTP/1.1" 200 -
INFO:werkzeug:127.0.0.1 - - [24/May/2020 23:14:37] "POST /recommender-places/criteria HTTP/1.1" 200 -
INFO:werkzeug:127.0.0.1 - - [24/May/2020 23:14:57] "POST /recommender-places/criteria HTTP/1.1" 200 -
INFO:werkzeug:127.0.0.1 - - [24/May/2020 23:15:18] "POST /recommender-places/criteria HTTP/1.1" 200 -
INFO:werkzeug:127.0.0.1 - - [24/May/2020 23:19:12] "POST /recommender-places/criteria HTTP/1.1" 200 -
INFO:werkzeug: * Running on http://0.0.0.0:8086/ (Press CTRL+C to quit)
INFO:werkzeug:127.0.0.1 - - [25/May/2020 23:50:37] "POST /recommender-places/criteria HTTP/1.1" 200 -
INFO:werkzeug:127.0.0.1 - - [25/May/2020 23:55:09] "POST /recommender-places/criteria HTTP/1.1" 200 -
